Workbook

Sheet Summary
A1: Bank Reconciliation Summary
A2: Run 0ED694B59281 | generated 2026-10-13 08:09:18 UTC | bank_reconciler v1.0.0
A4: 1. Population
A5: Bank transactions loaded | B5: =COUNTA(Bank_Txns!$A$5:$A$1134) -> 1130
A6: Ledger transactions loaded | B6: =COUNTA(Ledger_Txns!$A$5:$A$1140) -> 1136
A7: Bank statement - first date | B7: =MIN(Bank_Txns!$C$5:$C$1134) -> 46204
A8: Bank statement - last date | B8: =MAX(Bank_Txns!$C$5:$C$1134) -> 46295
A9: Bank net movement | B9: =SUM(Bank_Txns!$F$5:$F$1134) -> 16281055
A10: Ledger net movement | B10: =SUM(Ledger_Txns!$F$5:$F$1140) -> 15663728
A11: Net difference (Bank - Ledger) | B11: =B9-B10 -> 617327.09
A13: 2. Matching results
A14: Bank - clean matches | B14: =COUNTIF(Bank_Txns!$G$5:$G$1134,"MATCHED") -> 1068
A15: Bank - matched but flagged for review | B15: =COUNTIF(Bank_Txns!$G$5:$G$1134,"MATCHED-REVIEW") -> 34
A16: Bank - unmatched / duplicate | B16: =COUNTIF(Bank_Txns!$G$5:$G$1134,"UNMATCHED") -> 28
A17: Bank auto-match rate | B17: =IF(B5=0,0,(B14+B15)/B5) -> 0.97522124
A18: Ledger - clean matches | B18: =COUNTIF(Ledger_Txns!$G$5:$G$1140,"MATCHED") -> 1068
A19: Ledger - matched but flagged for review | B19: =COUNTIF(Ledger_Txns!$G$5:$G$1140,"MATCHED-REVIEW") -> 46
A20: Ledger - unmatched / duplicate | B20: =COUNTIF(Ledger_Txns!$G$5:$G$1140,"UNMATCHED") -> 22
A21: Ledger auto-match rate | B21: =IF(B6=0,0,(B18+B19)/B6) -> 0.9806338
A22: Match groups created | B22: =COUNTA(Matched!$A$5:$A$1106) -> 1102
A23: Matches with date variance > 0 days (informational) | B23: =COUNTIF(Matched!$H$5:$H$1106,">0") -> 747
A25: 3. Exceptions by type
A26: Exception type | B26: Count | C26: Net impact (Bank - Ledger) | D26: High | E26: Medium | F26: Low
A27: UNMATCHED_BANK | B27: =COUNTIF(Exceptions!$B$5:$B$88,$A27) -> 20 | C27: =SUMIFS(Exceptions!$M$5:$M$88,Exceptions!$B$5:$B$88,$A27) -> 10706.47 | D27: =COUNTIFS(Exceptions!$B$5:$B$88,$A27,Exceptions!$D$5:$D$88,"High") -> 4 | E27: =COUNTIFS(Exceptions!$B$5:$B$88,$A27,Exceptions!$D$5:$D$88,"Medium") -> 8 | F27: =COUNTIFS(Exceptions!$B$5:$B$88,$A27,Exceptions!$D$5:$D$88,"Low") -> 8
A28: UNMATCHED_LEDGER | B28: =COUNTIF(Exceptions!$B$5:$B$88,$A28) -> 14 | C28: =SUMIFS(Exceptions!$M$5:$M$88,Exceptions!$B$5:$B$88,$A28) -> 3729.98 | D28: =COUNTIFS(Exceptions!$B$5:$B$88,$A28,Exceptions!$D$5:$D$88,"High") -> 5 | E28: =COUNTIFS(Exceptions!$B$5:$B$88,$A28,Exceptions!$D$5:$D$88,"Medium") -> 9 | F28: =COUNTIFS(Exceptions!$B$5:$B$88,$A28,Exceptions!$D$5:$D$88,"Low") -> 0
A29: DUPLICATE_BANK | B29: =COUNTIF(Exceptions!$B$5:$B$88,$A29) -> 8 | C29: =SUMIFS(Exceptions!$M$5:$M$88,Exceptions!$B$5:$B$88,$A29) -> 495642.78 | D29: =COUNTIFS(Exceptions!$B$5:$B$88,$A29,Exceptions!$D$5:$D$88,"High") -> 8 | E29: =COUNTIFS(Exceptions!$B$5:$B$88,$A29,Exceptions!$D$5:$D$88,"Medium") -> 0 | F29: =COUNTIFS(Exceptions!$B$5:$B$88,$A29,Exceptions!$D$5:$D$88,"Low") -> 0
A30: DUPLICATE_LEDGER | B30: =COUNTIF(Exceptions!$B$5:$B$88,$A30) -> 8 | C30: =SUMIFS(Exceptions!$M$5:$M$88,Exceptions!$B$5:$B$88,$A30) -> 230109.02 | D30: =COUNTIFS(Exceptions!$B$5:$B$88,$A30,Exceptions!$D$5:$D$88,"High") -> 8 | E30: =COUNTIFS(Exceptions!$B$5:$B$88,$A30,Exceptions!$D$5:$D$88,"Medium") -> 0 | F30: =COUNTIFS(Exceptions!$B$5:$B$88,$A30,Exceptions!$D$5:$D$88,"Low") -> 0
A31: AMOUNT_MISMATCH | B31: =COUNTIF(Exceptions!$B$5:$B$88,$A31) -> 23 | C31: =SUMIFS(Exceptions!$M$5:$M$88,Exceptions!$B$5:$B$88,$A31) -> -122861.16 | D31: =COUNTIFS(Exceptions!$B$5:$B$88,$A31,Exceptions!$D$5:$D$88,"High") -> 3 | E31: =COUNTIFS(Exceptions!$B$5:$B$88,$A31,Exceptions!$D$5:$D$88,"Medium") -> 7 | F31: =COUNTIFS(Exceptions!$B$5:$B$88,$A31,Exceptions!$D$5:$D$88,"Low") -> 13
A32: LOW_CONFIDENCE_MATCH | B32: =COUNTIF(Exceptions!$B$5:$B$88,$A32) -> 5 | C32: =SUMIFS(Exceptions!$M$5:$M$88,Exceptions!$B$5:$B$88,$A32) -> 0 | D32: =COUNTIFS(Exceptions!$B$5:$B$88,$A32,Exceptions!$D$5:$D$88,"High") -> 0 | E32: =COUNTIFS(Exceptions!$B$5:$B$88,$A32,Exceptions!$D$5:$D$88,"Medium") -> 3 | F32: =COUNTIFS(Exceptions!$B$5:$B$88,$A32,Exceptions!$D$5:$D$88,"Low") -> 2
A33: SPLIT_MATCH | B33: =COUNTIF(Exceptions!$B$5:$B$88,$A33) -> 6 | C33: =SUMIFS(Exceptions!$M$5:$M$88,Exceptions!$B$5:$B$88,$A33) -> 0 | D33: =COUNTIFS(Exceptions!$B$5:$B$88,$A33,Exceptions!$D$5:$D$88,"High") -> 0 | E33: =COUNTIFS(Exceptions!$B$5:$B$88,$A33,Exceptions!$D$5:$D$88,"Medium") -> 6 | F33: =COUNTIFS(Exceptions!$B$5:$B$88,$A33,Exceptions!$D$5:$D$88,"Low") -> 0
A34: Total | B34: =SUM(B27:B33) -> 84 | C34: =SUM(C27:C33) -> 617327.09 | D34: =SUM(D27:D33) -> 28 | E34: =SUM(E27:E33) -> 33 | F34: =SUM(F27:F33) -> 23
A36: 4. Reconciliation bridge (control proof)
A37: Net difference (Bank - Ledger) | B37: =B11 -> 617327.09
A38: Less: amount differences inside matched pairs | B38: =SUM(Matched!$K$5:$K$1106) -> -122861.16
A39: Less: unmatched bank items | B39: =SUMIFS(Exceptions!$M$5:$M$88,Exceptions!$B$5:$B$88,"UNMATCHED_BANK") -> 10706.47
A40: Less: duplicate bank items | B40: =SUMIFS(Exceptions!$M$5:$M$88,Exceptions!$B$5:$B$88,"DUPLICATE_BANK") -> 495642.78
A41: Add back: unmatched ledger items | B41: =SUMIFS(Exceptions!$M$5:$M$88,Exceptions!$B$5:$B$88,"UNMATCHED_LEDGER") -> 3729.98
A42: Add back: duplicate ledger items | B42: =SUMIFS(Exceptions!$M$5:$M$88,Exceptions!$B$5:$B$88,"DUPLICATE_LEDGER") -> 230109.02
A43: Unexplained difference (must be 0.00) | B43: =B37-SUM(B38:B42) -> 0
A44: Control check | B44: =IF(ABS(B43)<0.005,"PASS - fully explained","FAIL - unexplained difference") -> PASS - fully explained
...

Sheet Exceptions
A1: Exception Report - for auditor review and sign-off
A2: Yellow columns P-S are reviewer inputs. Difference = Bank - Ledger. Every exception needs a disposition before sign-off (see Summary).
A4: Exception ID | B4: Type | C4: Sub-type | D4: Severity | E4: Bank Txn ID | F4: Ledger Txn ID | G4: Bank Date | H4: Ledger Date | I4: Reference | J4: Description | K4: Bank Amount | L4: Ledger Amount | M4: Difference (Bank - Ledger) | N4: Explanation (auto-generated) | O4: Suggested Action | P4: Disposition | Q4: Reviewer Comments | R4: Reviewed By | S4: Review Date
A5: EX0001 | B5: UNMATCHED_BANK | C5: UNRECORDED_RECEIPT | D5: High | E5: B00930 | G5: 46276 | J5: NEFT CR UNKNOWN REMITTER 7000 | K5: 21883.24 | M5: =N(K5)-N(L5) -> 21883.24 | N5: Bank line of 21,883.24 on 2026-09-11 has no corresponding ledger entry. | O5: Identify the payer; record receipt / allocate to open invoice, or query the bank.
A6: EX0002 | B6: UNMATCHED_BANK | C6: UNRECORDED_RECEIPT | D6: High | E6: B00332 | G6: 46229 | J6: NEFT CR UNKNOWN REMITTER 7002 | K6: 12055.87 | M6: =N(K6)-N(L6) -> 12055.87 | N6: Bank line of 12,055.87 on 2026-07-26 has no corresponding ledger entry. | O6: Identify the payer; record receipt / allocate to open invoice, or query the bank.
A7: EX0003 | B7: UNMATCHED_BANK | C7: UNRECORDED_RECEIPT | D7: High | E7: B00831 | G7: 46268 | J7: NEFT CR UNKNOWN REMITTER 7001 | K7: 10992.86 | M7: =N(K7)-N(L7) -> 10992.86 | N7: Bank line of 10,992.86 on 2026-09-03 has no corresponding ledger entry. | O7: Identify the payer; record receipt / allocate to open invoice, or query the bank.
A8: EX0004 | B8: UNMATCHED_BANK | C8: UNRECORDED_PAYMENT | D8: High | E8: B00791 | G8: 46265 | J8: DIRECT DEBIT INSURANCE PREMIUM | K8: -10494.74 | M8: =N(K8)-N(L8) -> -10494.74 | N8: Bank line of -10,494.74 on 2026-08-31 has no corresponding ledger entry. | O8: Obtain supporting document; record in ledger, or dispute if unauthorised.
A9: EX0005 | B9: UNMATCHED_LEDGER | C9: STALE_OUTSTANDING_PAYMENT | D9: High | F9: L00480 | H9: 46237 | I9: CHQ-009507 | J9: Cheque payment to Yonder Travel - CHQ-009507 | L9: -39929.07 | M9: =N(K9)-N(L9) -> 39929.07 | N9: Ledger entry of -39,929.07 on 2026-08-03 has no bank line. Recorded 58 days before statement end and still not cleared. | O9: Aged unpresented payment - confirm status with payee; consider stop-payment / reissue.
A10: EX0006 | B10: UNMATCHED_LEDGER | C10: STALE_OUTSTANDING_PAYMENT | D10: High | F10: L00237 | H10: 46220 | I10: CHQ-009500 | J10: Cheque payment to Kestrel Office Supplies - CHQ-009500 | L10: -36473.48 | M10: =N(K10)-N(L10) -> 36473.48 | N10: Ledger entry of -36,473.48 on 2026-07-17 has no bank line. Recorded 75 days before statement end and still not cleared. | O10: Aged unpresented payment - confirm status with payee; consider stop-payment / reissue.
A11: EX0007 | B11: UNMATCHED_LEDGER | C11: STALE_OUTSTANDING_PAYMENT | D11: High | F11: L00380 | H11: 46230 | I11: CHQ-009504 | J11: Cheque payment to Summit Security - CHQ-009504 | L11: -28024.92 | M11: =N(K11)-N(L11) -> 28024.92 | N11: Ledger entry of -28,024.92 on 2026-07-27 has no bank line. Recorded 65 days before statement end and still not cleared. | O11: Aged unpresented payment - confirm status with payee; consider stop-payment / reissue.
A12: EX0008 | B12: UNMATCHED_LEDGER | C12: STALE_OUTSTANDING_PAYMENT | D12: High | F12: L00905 | H12: 46272 | I12: CHQ-009501 | J12: Cheque payment to Pinnacle Print - CHQ-009501 | L12: -20819.16 | M12: =N(K12)-N(L12) -> 20819.16 | N12: Ledger entry of -20,819.16 on 2026-09-07 has no bank line. Recorded 23 days before statement end and still not cleared. | O12: Aged unpresented payment - confirm status with payee; consider stop-payment / reissue.
A13: EX0009 | B13: UNMATCHED_LEDGER | C13: STALE_OUTSTANDING_PAYMENT | D13: High | F13: L00107 | H13: 46210 | I13: CHQ-009503 | J13: Cheque payment to Orchid Catering - CHQ-009503 | L13: -20303.44 | M13: =N(K13)-N(L13) -> 20303.44 | N13: Ledger entry of -20,303.44 on 2026-07-07 has no bank line. Recorded 85 days before statement end and still not cleared. | O13: Aged unpresented payment - confirm status with payee; consider stop-payment / reissue.
A14: EX0010 | B14: DUPLICATE_BANK | C14: REPEATED_BANK_ENTRY | D14: High | E14: B00124 | G14: 46213 | I14: INV-1425 | J14: NEFT-EVEREST TEXTILES-INV1425 | K14: 91376.45 | M14: =N(K14)-N(L14) -> 91376.45 | N14: Identical to B00117 (2026-07-10, 91,376.45); only one ledger entry exists. | O14: Raise duplicate debit/credit claim with the bank and request reversal.
A15: EX0011 | B15: DUPLICATE_BANK | C15: REPEATED_BANK_ENTRY | D15: High | E15: B00960 | G15: 46278 | I15: INV-1098 | J15: NEFT-BLUEFIN LOGISTICS-INV1098 | K15: 87563.78 | M15: =N(K15)-N(L15) -> 87563.78 | N15: Identical to B00947 (2026-09-13, 87,563.78); only one ledger entry exists. | O15: Raise duplicate debit/credit claim with the bank and request reversal.
A16: EX0012 | B16: DUPLICATE_BANK | C16: REPEATED_BANK_ENTRY | D16: High | E16: B00160 | G16: 46216 | I16: 1230 | J16: NEFT-BLUEFIN LOGISTICS-INV1230 | K16: 74966.87 | M16: =N(K16)-N(L16) -> 74966.87 | N16: Identical to B00148 (2026-07-13, 74,966.87); only one ledger entry exists. | O16: Raise duplicate debit/credit claim with the bank and request reversal.
A17: EX0013 | B17: DUPLICATE_BANK | C17: REPEATED_BANK_ENTRY | D17: High | E17: B00389 | G17: 46233 | I17: INV-1052 | J17: NEFT-DELTA FOODS-INV1052 | K17: 71068.32 | M17: =N(K17)-N(L17) -> 71068.32 | N17: Identical to B00380 (2026-07-30, 71,068.32); only one ledger entry exists. | O17: Raise duplicate debit/credit claim with the bank and request reversal.
A18: EX0014 | B18: DUPLICATE_BANK | C18: REPEATED_BANK_ENTRY | D18: High | E18: B00845 | G18: 46269 | I18: 1094 | J18: NEFT-JUPITER STEEL-INV1094 | K18: 60401.29 | M18: =N(K18)-N(L18) -> 60401.29 | N18: Identical to B00832 (2026-09-04, 60,401.29); only one ledger entry exists. | O18: Raise duplicate debit/credit claim with the bank and request reversal.
A19: EX0015 | B19: DUPLICATE_BANK | C19: REPEATED_BANK_ENTRY | D19: High | E19: B00631 | G19: 46253 | I19: 1264 | J19: NEFT-LAKEVIEW HOTELS-INV1264 | K19: 60241.9 | M19: =N(K19)-N(L19) -> 60241.9 | N19: Identical to B00620 (2026-08-19, 60,241.90); only one ledger entry exists. | O19: Raise duplicate debit/credit claim with the bank and request reversal.
A20: EX0016 | B20: DUPLICATE_BANK | C20: REPEATED_BANK_ENTRY | D20: High | E20: B00362 | G20: 46231 | I20: INV-1207 | J20: NEFT-CRESTVIEW RETAIL-INV1207 | K20: 39198.32 | M20: =N(K20)-N(L20) -> 39198.32 | N20: Identical to B00351 (2026-07-28, 39,198.32); only one ledger entry exists. | O20: Raise duplicate debit/credit claim with the bank and request reversal.
A21: EX0017 | B21: DUPLICATE_BANK | C21: REPEATED_BANK_ENTRY | D21: High | E21: B00914 | G21: 46275 | I21: INV-1477 | J21: NEFT-INDUS PACKAGING-INV1477 | K21: 10825.85 | M21: =N(K21)-N(L21) -> 10825.85 | N21: Identical to B00908 (2026-09-10, 10,825.85); only one ledger entry exists. | O21: Raise duplicate debit/credit claim with the bank and request reversal.
A22: EX0018 | B22: DUPLICATE_LEDGER | C22: DOUBLE_POSTED_ENTRY | D22: High | F22: L00267 | H22: 46222 | I22: CHQ-005362 | J22: Cheque payment to Pinnacle Print - CHQ-005362 | L22: -52959.94 | M22: =N(K22)-N(L22) -> 52959.94 | N22: Identical to L00265 (2026-07-19, -52,959.94); only one bank line exists. | O22: Verify against source document and reverse the duplicate ledger entry.
A23: EX0019 | B23: DUPLICATE_LEDGER | C23: DOUBLE_POSTED_ENTRY | D23: High | F23: L00347 | H23: 46228 | I23: CHQ-005080 | J23: Cheque payment to Birch Packaging - CHQ-005080 | L23: -45627.98 | M23: =N(K23)-N(L23) -> 45627.98 | N23: Identical to L00344 (2026-07-25, -45,627.98); only one bank line exists. | O23: Verify against source document and reverse the duplicate ledger entry.
A24: EX0020 | B24: DUPLICATE_LEDGER | C24: DOUBLE_POSTED_ENTRY | D24: High | F24: L00984 | H24: 46278 | I24: CHQ-005445 | J24: Cheque payment to Summit Security - CHQ-005445 | L24: -29594.73 | M24: =N(K24)-N(L24) -> 29594.73 | N24: Identical to L00983 (2026-09-13, -29,594.73); only one bank line exists. | O24: Verify against source document and reverse the duplicate ledger entry.
A25: EX0021 | B25: DUPLICATE_LEDGER | C25: DOUBLE_POSTED_ENTRY | D25: High | F25: L00818 | H25: 46265 | I25: CHQ-005227 | J25: Cheque payment to Willow Furnishings - CHQ-005227 | L25: -29486.63 | M25: =N(K25)-N(L25) -> 29486.63 | N25: Identical to L00816 (2026-08-31, -29,486.63); only one bank line exists. | O25: Verify against source document and reverse the duplicate ledger entry.
A26: EX0022 | B26: DUPLICATE_LEDGER | C26: DOUBLE_POSTED_ENTRY | D26: High | F26: L00506 | H26: 46240 | I26: CHQ-005357 | J26: Cheque payment to Willow Furnishings - CHQ-005357 | L26: -27497.54 | M26: =N(K26)-N(L26) -> 27497.54 | N26: Identical to L00505 (2026-08-06, -27,497.54); only one bank line exists. | O26: Verify against source document and reverse the duplicate ledger entry.
A27: EX0023 | B27: DUPLICATE_LEDGER | C27: DOUBLE_POSTED_ENTRY | D27: High | F27: L00764 | H27: 46261 | I27: CHQ-005218 | J27: Cheque payment to Yonder Travel - CHQ-005218 | L27: -21584.07 | M27: =N(K27)-N(L27) -> 21584.07 | N27: Identical to L00760 (2026-08-27, -21,584.07); only one bank line exists. | O27: Verify against source document and reverse the duplicate ledger entry.
A28: EX0024 | B28: DUPLICATE_LEDGER | C28: DOUBLE_POSTED_ENTRY | D28: High | F28: L01029 | H28: 46281 | I28: CHQ-005030 | J28: Cheque payment to Birch Packaging - CHQ-005030 | L28: -12313.56 | M28: =N(K28)-N(L28) -> 12313.56 | N28: Identical to L01021 (2026-09-16, -12,313.56); only one bank line exists. | O28: Verify against source document and reverse the duplicate ledger entry.
A29: EX0025 | B29: DUPLICATE_LEDGER | C29: DOUBLE_POSTED_ENTRY | D29: High | F29: L00479 | H29: 46237 | I29: CHQ-005352 | J29: Cheque payment to Pinnacle Print - CHQ-005352 | L29: -11044.57 | M29: =N(K29)-N(L29) -> 11044.57 | N29: Identical to L00476 (2026-08-03, -11,044.57); only one bank line exists. | O29: Verify against source document and reverse the duplicate ledger entry.
A30: EX0026 | B30: AMOUNT_MISMATCH | C30: SIGN_REVERSAL | D30: High | E30: B00253 | F30: L00236 | G30: 46223 | H30: 46220 | I30: 009004 | J30: B: CHQ 009004 ORCHID CATERING | L: Cheque payment to Orchid Catering - CHQ-009004 | K30: -19757.52 | L30: 19757.52 | M30: =N(K30)-N(L30) -> -39515.04 | N30: Bank -19,757.52 vs ledger 19,757.52 (difference -39,515.04). Amounts are equal and opposite; ledger entry was likely posted with the wrong sign. | O30: Correct the ledger entry sign (reverse and re-post).
A31: EX0027 | B31: AMOUNT_MISMATCH | C31: SIGN_REVERSAL | D31: High | E31: B00200 | F31: L00184 | G31: 46219 | H31: 46216 | I31: 009003 | J31: B: CHQ 009003 ZENITH HARDWARE | L: Cheque payment to Zenith Hardware - CHQ-009003 | K31: -15887.58 | L31: 15887.58 | M31: =N(K31)-N(L31) -> -31775.16 | N31: Bank -15,887.58 vs ledger 15,887.58 (difference -31,775.16). Amounts are equal and opposite; ledger entry was likely posted with the wrong sign. | O31: Correct the ledger entry sign (reverse and re-post).
A32: EX0028 | B32: AMOUNT_MISMATCH | C32: SIGN_REVERSAL | D32: High | E32: B00057 | F32: L00072 | G32: 46208 | H32: 46208 | I32: 009002 | J32: B: CHQ 009002 PINNACLE PRINT | L: Cheque payment to Pinnacle Print - CHQ-009002 | K32: -14380.51 | L32: 14380.51 | M32: =N(K32)-N(L32) -> -28761.02 | N32: Bank -14,380.51 vs ledger 14,380.51 (difference -28,761.02). Amounts are equal and opposite; ledger entry was likely posted with the wrong sign. | O32: Correct the ledger entry sign (reverse and re-post).
A33: EX0029 | B33: UNMATCHED_BANK | C33: UNRECORDED_PAYMENT | D33: Medium | E33: B00817 | G33: 46267 | J33: DIRECT DEBIT PROFESSIONAL BODY | K33: -9573.14 | M33: =N(K33)-N(L33) -> -9573.14 | N33: Bank line of -9,573.14 on 2026-09-02 has no corresponding ledger entry. | O33: Obtain supporting document; record in ledger, or dispute if unauthorised.
A34: EX0030 | B34: UNMATCHED_BANK | C34: UNRECORDED_RECEIPT | D34: Medium | E34: B00915 | G34: 46275 | J34: NEFT CR UNKNOWN REMITTER 7003 | K34: 8934.87 | M34: =N(K34)-N(L34) -> 8934.87 | N34: Bank line of 8,934.87 on 2026-09-10 has no corresponding ledger entry. | O34: Identify the payer; record receipt / allocate to open invoice, or query the bank.
A35: EX0031 | B35: UNMATCHED_BANK | C35: UNRECORDED_PAYMENT | D35: Medium | E35: B00762 | G35: 46263 | J35: SI MAINTENANCE | K35: -8887.16 | M35: =N(K35)-N(L35) -> -8887.16 | N35: Bank line of -8,887.16 on 2026-08-29 has no corresponding ledger entry. | O35: Obtain supporting document; record in ledger, or dispute if unauthorised.
A36: EX0032 | B36: UNMATCHED_BANK | C36: UNRECORDED_PAYMENT | D36: Medium | E36: B00887 | G36: 46273 | J36: EMI AUTO DEBIT EQUIPMENT | K36: -5292.31 | M36: =N(K36)-N(L36) -> -5292.31 | N36: Bank line of -5,292.31 on 2026-09-08 has no corresponding ledger entry. | O36: Obtain supporting document; record in ledger, or dispute if unauthorised.
A37: EX0033 | B37: UNMATCHED_BANK | C37: UNRECORDED_PAYMENT | D37: Medium | E37: B00406 | G37: 46234 | J37: STANDING INSTRUCTION RENT | K37: -5277.99 | M37: =N(K37)-N(L37) -> -5277.99 | N37: Bank line of -5,277.99 on 2026-07-31 has no corresponding ledger entry. | O37: Obtain supporting document; record in ledger, or dispute if unauthorised.
A38: EX0034 | B38: UNMATCHED_BANK | C38: UNRECORDED_PAYMENT | D38: Medium | E38: B00454 | G38: 46237 | J38: EMI AUTO DEBIT LOAN | K38: -4632.37 | M38: =N(K38)-N(L38) -> -4632.37 | N38: Bank line of -4,632.37 on 2026-08-03 has no corresponding ledger entry. | O38: Obtain supporting document; record in ledger, or dispute if unauthorised.
A39: EX0035 | B39: UNMATCHED_BANK | C39: UNRECORDED_BANK_CHARGE_OR_INTEREST | D39: Medium | E39: B00973 | G39: 46279 | J39: INTEREST CREDIT SEP | K39: 2558.43 | M39: =N(K39)-N(L39) -> 2558.43 | N39: Bank line of 2,558.43 on 2026-09-14 has no corresponding ledger entry. | O39: Verify with bank advice, then post journal in the ledger.
A40: EX0036 | B40: UNMATCHED_BANK | C40: UNRECORDED_BANK_CHARGE_OR_INTEREST | D40: Medium | E40: B00790 | G40: 46265 | J40: INTEREST CREDIT AUG | K40: 2056.81 | M40: =N(K40)-N(L40) -> 2056.81 | N40: Bank line of 2,056.81 on 2026-08-31 has no corresponding ledger entry. | O40: Verify with bank advice, then post journal in the ledger.
A41: EX0037 | B41: UNMATCHED_LEDGER | C41: OUTSTANDING_IN_TRANSIT | D41: Medium | F41: L01133 | H41: 46292 | I41: INV-9404 | J41: Deposit in transit - Everest Textiles INV-9404 | L41: 49817.86 | M41: =N(K41)-N(L41) -> -49817.86 | N41: Ledger entry of 49,817.86 on 2026-09-27 has no bank line. Recorded 3 day(s) before statement end; likely still in transit. | O41: Timing difference - confirm it clears on the next statement; carry forward.
...

Sheet Matched
A1: Matched Transactions (audit log of every pairing)
A2: Dates shown are the latest date in a group. Flag column links to the exception raised, if any.
A4: Match ID | B4: Rule | C4: Confidence | D4: Bank Txn ID(s) | E4: Ledger Txn ID(s) | F4: Bank Date | G4: Ledger Date | H4: Date Variance (days) | I4: Bank Amount | J4: Ledger Amount | K4: Difference | L4: Bank Description | M4: Ledger Description | N4: Exception Flag
A5: M00001 | B5: R1 Reference + Amount | C5: 1 | D5: B00001 | E5: L00002 | F5: 46204 | G5: 46204 | H5: =ABS(F5-G5) -> 0 | I5: 74471.27 | J5: 74471.27 | K5: =I5-J5 -> 0 | L5: NEFT-INDUS PACKAGING-INV1189 | M5: Receipt from Indus Packaging - INV-1189
A6: M00002 | B6: R1 Reference + Amount | C6: 1 | D6: B00002 | E6: L00005 | F6: 46204 | G6: 46204 | H6: =ABS(F6-G6) -> 0 | I6: 85406.51 | J6: 85406.51 | K6: =I6-J6 -> 0 | L6: NEFT-CRESTVIEW RETAIL-INV1303 | M6: Receipt from Crestview Retail - INV-1303
A7: M00003 | B7: R1 Reference + Amount | C7: 1 | D7: B00003 | E7: L00006 | F7: 46204 | G7: 46204 | H7: =ABS(F7-G7) -> 0 | I7: 25861.73 | J7: 25861.73 | K7: =I7-J7 -> 0 | L7: NEFT-CRESTVIEW RETAIL-INV1315 | M7: Receipt from Crestview Retail - INV-1315
A8: M00004 | B8: R1 Reference + Amount | C8: 1 | D8: B00004 | E8: L00007 | F8: 46204 | G8: 46204 | H8: =ABS(F8-G8) -> 0 | I8: 80253.44 | J8: 80253.44 | K8: =I8-J8 -> 0 | L8: NEFT-INDUS PACKAGING-INV1333 | M8: Receipt from Indus Packaging - INV-1333
A9: M00005 | B9: R1 Reference + Amount | C9: 1 | D9: B00005 | E9: L00009 | F9: 46204 | G9: 46204 | H9: =ABS(F9-G9) -> 0 | I9: 70918.12 | J9: 70918.12 | K9: =I9-J9 -> 0 | L9: NEFT-HORIZON PHARMA-INV1380 | M9: Receipt from Horizon Pharma - INV-1380
A10: M00006 | B10: R1 Reference + Amount | C10: 1 | D10: B00006 | E10: L00010 | F10: 46204 | G10: 46204 | H10: =ABS(F10-G10) -> 0 | I10: 58163.35 | J10: 58163.35 | K10: =I10-J10 -> 0 | L10: NEFT-BLUEFIN LOGISTICS-INV1422 | M10: Receipt from Bluefin Logistics - INV-1422
A11: M00007 | B11: R1 Reference + Amount | C11: 1 | D11: B00007 | E11: L00011 | F11: 46204 | G11: 46204 | H11: =ABS(F11-G11) -> 0 | I11: 30637.39 | J11: 30637.39 | K11: =I11-J11 -> 0 | L11: NEFT-GREENLEAF AGRO-INV1439 | M11: Receipt from Greenleaf Agro - INV-1439
A12: M00008 | B12: R1 Reference + Amount | C12: 1 | D12: B00008 | E12: L00013 | F12: 46204 | G12: 46204 | H12: =ABS(F12-G12) -> 0 | I12: 16321.38 | J12: 16321.38 | K12: =I12-J12 -> 0 | L12: NEFT-LAKEVIEW HOTELS-INV1504 | M12: Receipt from Lakeview Hotels - INV-1504
A13: M00009 | B13: R1 Reference + Amount | C13: 1 | D13: B00009 | E13: L00016 | F13: 46204 | G13: 46204 | H13: =ABS(F13-G13) -> 0 | I13: -34728.88 | J13: -34728.88 | K13: =I13-J13 -> 0 | L13: CHQ 005099 ATLAS FREIGHT | M13: Cheque payment to Atlas Freight - CHQ-005099
A14: M00010 | B14: R1 Reference + Amount | C14: 1 | D14: B00013 | E14: L00021 | F14: 46205 | G14: 46205 | H14: =ABS(F14-G14) -> 0 | I14: 17593.36 | J14: 17593.36 | K14: =I14-J14 -> 0 | L14: NEFT-JUPITER STEEL-INV1310 | M14: Receipt from Jupiter Steel - INV-1310
A15: M00011 | B15: R1 Reference + Amount | C15: 1 | D15: B00015 | E15: L00023 | F15: 46205 | G15: 46205 | H15: =ABS(F15-G15) -> 0 | I15: 58735.72 | J15: 58735.72 | K15: =I15-J15 -> 0 | L15: NEFT-BLUEFIN LOGISTICS-INV1470 | M15: Receipt from Bluefin Logistics - INV-1470
A16: M00012 | B16: R1 Reference + Amount | C16: 1 | D16: B00017 | E16: L00027 | F16: 46205 | G16: 46205 | H16: =ABS(F16-G16) -> 0 | I16: -56444.22 | J16: -56444.22 | K16: =I16-J16 -> 0 | L16: CHQ 005287 WILLOW FURNISHINGS | M16: Cheque payment to Willow Furnishings - CHQ-005287
... A1072: M01068 | B1072: R2 Amount + Date + Description | C1072: 0.85 | D1072: B01064 | E1072: L01054 | F1072: 46285 | G1072: 46283 | H1072: =ABS(F1072-G1072) -> 2 | I1072: -3020.43 | J1072: -3020.43 | K1072: =I1072-J1072 -> 0 | L1072: ACH-RAPID REPAIRS | M1072: Rapid Repairs - bill
A1073: M01069 | B1073: R3 Reference match, amount differs | C1073: 0.95 | D1073: B00057 | E1073: L00072 | F1073: 46208 | G1073: 46208 | H1073: =ABS(F1073-G1073) -> 0 | I1073: -14380.51 | J1073: 14380.51 | K1073: =I1073-J1073 -> -28761.02 | L1073: CHQ 009002 PINNACLE PRINT | M1073: Cheque payment to Pinnacle Print - CHQ-009002 | N1073: EX0028
A1074: M01070 | B1074: R3 Reference match, amount differs | C1074: 0.95 | D1074: B00144 | E1074: L00171 | F1074: 46215 | G1074: 46215 | H1074: =ABS(F1074-G1074) -> 0 | I1074: 45886.89 | J1074: 45928.97 | K1074: =I1074-J1074 -> -42.08 | L1074: WIRE-ACME TRADERS-INV9200 | M1074: Receipt from Acme Traders - INV-9200 | N1074: EX0076
A1075: M01071 | B1075: R3 Reference match, amount differs | C1075: 0.95 | D1075: B00505 | E1075: L00535 | F1075: 46242 | G1075: 46242 | H1075: =ABS(F1075-G1075) -> 0 | I1075: 23572.15 | J1075: 23572.72 | K1075: =I1075-J1075 -> -0.57 | L1075: NEFT-ACME TRADERS-INV9300 | M1075: Receipt from Acme Traders - INV-9300 | N1075: EX0079
A1076: M01072 | B1076: R3 Reference match, amount differs | C1076: 0.95 | D1076: B00583 | E1076: L00614 | F1076: 46249 | G1076: 46249 | H1076: =ABS(F1076-G1076) -> 0 | I1076: 13548.95 | J1076: 13577.96 | K1076: =I1076-J1076 -> -29.01 | L1076: WIRE-CRESTVIEW RETAIL-INV9202 | M1076: Receipt from Crestview Retail - INV-9202 | N1076: EX0077
A1077: M01073 | B1077: R3 Reference match, amount differs | C1077: 0.95 | D1077: B00775 | E1077: L00801 | F1077: 46264 | G1077: 46264 | H1077: =ABS(F1077-G1077) -> 0 | I1077: 20044.73 | J1077: 20099.37 | K1077: =I1077-J1077 -> -54.64 | L1077: WIRE-HORIZON PHARMA-INV9207 | M1077: Receipt from Horizon Pharma - INV-9207 | N1077: EX0074
A1078: M01074 | B1078: R3 Reference match, amount differs | C1078: 0.95 | D1078: B00990 | E1078: L01010 | F1078: 46280 | G1078: 46280 | H1078: =ABS(F1078-G1078) -> 0 | I1078: 69690.98 | J1078: 69799.41 | K1078: =I1078-J1078 -> -108.43 | L1078: WIRE-GREENLEAF AGRO-INV9206 | M1078: Receipt from Greenleaf Agro - INV-9206 | N1078: EX0071
A1079: M01075 | B1079: R3 Reference match, amount differs | C1079: 0.945 | D1079: B00044 | E1079: L00046 | F1079: 46207 | G1079: 46206 | H1079: =ABS(F1079-G1079) -> 1 | I1079: 41606.63 | J1079: 41743.69 | K1079: =I1079-J1079 -> -137.06 | L1079: WIRE-EVEREST TEXTILES-INV9204 | M1079: Receipt from Everest Textiles - INV-9204 | N1079: EX0070
A1080: M01076 | B1080: R3 Reference match, amount differs | C1080: 0.945 | D1080: B00161 | E1080: L00172 | F1080: 46216 | G1080: 46215 | H1080: =ABS(F1080-G1080) -> 1 | I1080: 71661.98 | J1080: 71704.47 | K1080: =I1080-J1080 -> -42.49 | L1080: WIRE-FALCON AUTO PARTS-INV9205 | M1080: Receipt from Falcon Auto Parts - INV-9205 | N1080: EX0075
A1081: M01077 | B1081: R3 Reference match, amount differs | C1081: 0.945 | D1081: B00272 | E1081: L00286 | F1081: 46224 | G1081: 46223 | H1081: =ABS(F1081-G1081) -> 1 | I1081: 52468.86 | J1081: 52648.86 | K1081: =I1081-J1081 -> -180 | L1081: NEFT-CRESTVIEW RETAIL-INV9102 | M1081: Receipt from Crestview Retail - INV-9102 | N1081: EX0052
A1082: M01078 | B1082: R3 Reference match, amount differs | C1082: 0.945 | D1082: B00283 | E1082: L00303 | F1082: 46225 | G1082: 46224 | H1082: =ABS(F1082-G1082) -> 1 | I1082: 13638.48 | J1082: 16338.48 | K1082: =I1082-J1082 -> -2700 | L1082: NEFT-ACME TRADERS-INV9100 | M1082: Receipt from Acme Traders - INV-9100 | N1082: EX0050
A1083: M01079 | B1083: R3 Reference match, amount differs | C1083: 0.945 | D1083: B00309 | E1083: L00322 | F1083: 46227 | G1083: 46226 | H1083: =ABS(F1083-G1083) -> 1 | I1083: 12701.31 | J1083: 12700.94 | K1083: =I1083-J1083 -> 0.37 | L1083: NEFT-CRESTVIEW RETAIL-INV9302 | M1083: Receipt from Crestview Retail - INV-9302 | N1083: EX0080
A1084: M01080 | B1084: R3 Reference match, amount differs | C1084: 0.945 | D1084: B00607 | E1084: L00626 | F1084: 46251 | G1084: 46250 | H1084: =ABS(F1084-G1084) -> 1 | I1084: 10648.31 | J1084: 10648.46 | K1084: =I1084-J1084 -> -0.15 | L1084: NEFT-DELTA FOODS-INV9303 | M1084: Receipt from Delta Foods - INV-9303 | N1084: EX0081
... A1106: M01102 | B1106: R5 Split / batch (1:N) | C1106: 0.5 | D1106: B00633 | E1106: L00643; L00644; L00634 | F1106: 46253 | G1106: 46252 | H1106: =ABS(F1106-G1106) -> 1 | I1106: 11448.33 | J1106: 11448.33 | K1106: =I1106-J1106 -> 0 | L1106: CASH DEPOSIT BATCH 006 | M1106: Cash receipt counter 2 - batch 6 | N1106: EX0061

Sheet Bank_Txns
A1: Bank Transactions - full population with reconciliation status
A2: Status: MATCHED = clean, MATCHED-REVIEW = paired but flagged, UNMATCHED = exception raised.
A4: Txn ID | B4: Source Row | C4: Date | D4: Description | E4: Reference | F4: Amount | G4: Status | H4: Match ID | I4: Exception ID
A5: B00001 | B5: 2 | C5: 46204 | D5: NEFT-INDUS PACKAGING-INV1189 | F5: 74471.27 | G5: MATCHED | H5: M00001
A6: B00002 | B6: 3 | C6: 46204 | D6: NEFT-CRESTVIEW RETAIL-INV1303 | F6: 85406.51 | G6: MATCHED | H6: M00002
A7: B00003 | B7: 4 | C7: 46204 | D7: NEFT-CRESTVIEW RETAIL-INV1315 | F7: 25861.73 | G7: MATCHED | H7: M00003
A8: B00004 | B8: 5 | C8: 46204 | D8: NEFT-INDUS PACKAGING-INV1333 | E8: INV-1333 | F8: 80253.44 | G8: MATCHED | H8: M00004
A9: B00005 | B9: 6 | C9: 46204 | D9: NEFT-HORIZON PHARMA-INV1380 | E9: INV-1380 | F9: 70918.12 | G9: MATCHED | H9: M00005
A10: B00006 | B10: 7 | C10: 46204 | D10: NEFT-BLUEFIN LOGISTICS-INV1422 | E10: INV-1422 | F10: 58163.35 | G10: MATCHED | H10: M00006
A11: B00007 | B11: 8 | C11: 46204 | D11: NEFT-GREENLEAF AGRO-INV1439 | F11: 30637.39 | G11: MATCHED | H11: M00007
A12: B00008 | B12: 9 | C12: 46204 | D12: NEFT-LAKEVIEW HOTELS-INV1504 | E12: INV-1504 | F12: 16321.38 | G12: MATCHED | H12: M00008
A13: B00009 | B13: 10 | C13: 46204 | D13: CHQ 005099 ATLAS FREIGHT | E13: 005099 | F13: -34728.88 | G13: MATCHED | H13: M00009
A14: B00010 | B14: 11 | C14: 46205 | D14: NEFT-ACME TRADERS-INV1157 | E14: INV-1157 | F14: 80301.26 | G14: MATCHED | H14: M00337
A15: B00011 | B15: 12 | C15: 46205 | D15: NEFT-INDUS PACKAGING-INV1201 | E15: INV-1201 | F15: 39464.96 | G15: MATCHED | H15: M00338
A16: B00012 | B16: 13 | C16: 46205 | D16: NEFT-HORIZON PHARMA-INV1260 | E16: INV-1260 | F16: 40257.56 | G16: MATCHED | H16: M00339
A17: B00013 | B17: 14 | C17: 46205 | D17: NEFT-JUPITER STEEL-INV1310 | E17: INV-1310 | F17: 17593.36 | G17: MATCHED | H17: M00010
A18: B00014 | B18: 15 | C18: 46205 | D18: NEFT-GREENLEAF AGRO-INV1355 | E18: INV-1355 | F18: 92963.64 | G18: MATCHED | H18: M00340
A19: B00015 | B19: 16 | C19: 46205 | D19: NEFT-BLUEFIN LOGISTICS-INV1470 | E19: INV-1470 | F19: 58735.72 | G19: MATCHED | H19: M00011
A20: B00016 | B20: 17 | C20: 46205 | D20: NEFT-EVEREST TEXTILES-INV1473 | E20: INV-1473 | F20: 29064.46 | G20: MATCHED | H20: M00341
A21: B00017 | B21: 18 | C21: 46205 | D21: CHQ 005287 WILLOW FURNISHINGS | E21: 005287 | F21: -56444.22 | G21: MATCHED | H21: M00012
A22: B00018 | B22: 19 | C22: 46205 | D22: CHQ 005314 ORCHID CATERING | E22: 005314 | F22: -6914.35 | G22: MATCHED | H22: M00013
A23: B00019 | B23: 20 | C23: 46205 | D23: CHQ 005428 YONDER TRAVEL | E23: 005428 | F23: -34476.01 | G23: MATCHED | H23: M00014
... A26: B00022 | B26: 23 | C26: 46206 | D26: NEFT-FALCON AUTO PARTS-INV1102 | E26: INV-1102 | F26: 14194.34 | G26: MATCHED | H26: M00343
A27: B00023 | B27: 24 | C27: 46206 | D27: NEFT-DELTA FOODS-INV1184 | F27: 31705.47 | G27: MATCHED | H27: M00016
A28: B00024 | B28: 25 | C28: 46206 | D28: NEFT-GREENLEAF AGRO-INV1379 | E28: INV-1379 | F28: 30251.62 | G28: MATCHED | H28: M00017
A29: B00025 | B29: 26 | C29: 46206 | D29: NEFT-DELTA FOODS-INV1388 | E29: INV-1388 | F29: 33180.93 | G29: MATCHED | H29: M00344
A30: B00026 | B30: 27 | C30: 46206 | D30: NEFT-LAKEVIEW HOTELS-INV1480 | E30: INV-1480 | F30: 56947.73 | G30: MATCHED | H30: M00345
A31: B00027 | B31: 28 | C31: 46206 | D31: NEFT-HORIZON PHARMA-INV1512 | E31: INV-1512 | F31: 38427.28 | G31: MATCHED | H31: M00018
A32: B00028 | B32: 29 | C32: 46206 | D32: NEFT-JUPITER STEEL-INV1526 | E32: INV-1526 | F32: 15893.2 | G32: MATCHED | H32: M00656
A33: B00029 | B33: 30 | C33: 46206 | D33: NEFT-DELTA FOODS-INV1544 | E33: INV-1544 | F33: 52434.49 | G33: MATCHED | H33: M00019
A34: B00030 | B34: 31 | C34: 46206 | D34: NEFT-DELTA FOODS-INV1568 | F34: 14196.36 | G34: MATCHED | H34: M00346
A35: B00031 | B35: 32 | C35: 46206 | D35: CHQ 005023 ZENITH HARDWARE | E35: 005023 | F35: -24979.35 | G35: MATCHED | H35: M00657
A36: B00032 | B36: 33 | C36: 46206 | D36: CHQ 005333 ZENITH HARDWARE | E36: 005333 | F36: -58473.02 | G36: MATCHED | H36: M00347
A37: B00033 | B37: 34 | C37: 46207 | D37: NEFT-EVEREST TEXTILES-INV1053 | E37: INV-1053 | F37: 35711.75 | G37: MATCHED | H37: M00020
A38: B00034 | B38: 35 | C38: 46207 | D38: NEFT-ACME TRADERS-INV1073 | E38: INV-1073 | F38: 51162.61 | G38: MATCHED | H38: M00348
A39: B00035 | B39: 36 | C39: 46207 | D39: NEFT-INDUS PACKAGING-INV1093 | E39: INV-1093 | F39: 45197.71 | G39: MATCHED | H39: M00349
A40: B00036 | B40: 37 | C40: 46207 | D40: NEFT-JUPITER STEEL-INV1178 | E40: INV-1178 | F40: 55404.83 | G40: MATCHED | H40: M00350
A41: B00037 | B41: 38 | C41: 46207 | D41: NEFT-BLUEFIN LOGISTICS-INV1194 | E41: INV-1194 | F41: 58297.6 | G41: MATCHED | H41: M00658
A42: B00038 | B42: 39 | C42: 46207 | D42: NEFT-BLUEFIN LOGISTICS-INV1338 | F42: 67468.06 | G42: MATCHED | H42: M00021
A43: B00039 | B43: 40 | C43: 46207 | D43: NEFT-HORIZON PHARMA-INV1392 | E43: INV-1392 | F43: 46767.67 | G43: MATCHED | H43: M00351
...

Sheet Ledger_Txns
A1: Ledger Transactions - full population with reconciliation status
A2: Status: MATCHED = clean, MATCHED-REVIEW = paired but flagged, UNMATCHED = exception raised.
A4: Txn ID | B4: Source Row | C4: Date | D4: Description | E4: Reference | F4: Amount | G4: Status | H4: Match ID | I4: Exception ID
A5: L00001 | B5: 2 | C5: 46204 | D5: Receipt from Acme Traders - INV-1157 | E5: INV-1157 | F5: 80301.26 | G5: MATCHED | H5: M00337
A6: L00002 | B6: 3 | C6: 46204 | D6: Receipt from Indus Packaging - INV-1189 | E6: INV-1189 | F6: 74471.27 | G6: MATCHED | H6: M00001
A7: L00003 | B7: 4 | C7: 46204 | D7: Receipt from Indus Packaging - INV-1201 | E7: INV-1201 | F7: 39464.96 | G7: MATCHED | H7: M00338
A8: L00004 | B8: 5 | C8: 46204 | D8: Receipt from Horizon Pharma - INV-1260 | E8: INV-1260 | F8: 40257.56 | G8: MATCHED | H8: M00339
A9: L00005 | B9: 6 | C9: 46204 | D9: Receipt from Crestview Retail - INV-1303 | E9: INV-1303 | F9: 85406.51 | G9: MATCHED | H9: M00002
A10: L00006 | B10: 7 | C10: 46204 | D10: Receipt from Crestview Retail - INV-1315 | E10: INV-1315 | F10: 25861.73 | G10: MATCHED | H10: M00003
A11: L00007 | B11: 8 | C11: 46204 | D11: Receipt from Indus Packaging - INV-1333 | E11: INV-1333 | F11: 80253.44 | G11: MATCHED | H11: M00004
A12: L00008 | B12: 9 | C12: 46204 | D12: Receipt from Greenleaf Agro - INV-1355 | E12: INV-1355 | F12: 92963.64 | G12: MATCHED | H12: M00340
A13: L00009 | B13: 10 | C13: 46204 | D13: Receipt from Horizon Pharma - INV-1380 | E13: INV-1380 | F13: 70918.12 | G13: MATCHED | H13: M00005
A14: L00010 | B14: 11 | C14: 46204 | D14: Receipt from Bluefin Logistics - INV-1422 | E14: INV-1422 | F14: 58163.35 | G14: MATCHED | H14: M00006
A15: L00011 | B15: 12 | C15: 46204 | D15: Receipt from Greenleaf Agro - INV-1439 | E15: INV-1439 | F15: 30637.39 | G15: MATCHED | H15: M00007
A16: L00012 | B16: 13 | C16: 46204 | D16: Receipt from Everest Textiles - INV-1473 | E16: INV-1473 | F16: 29064.46 | G16: MATCHED | H16: M00341
... A49: L00045 | B49: 46 | C49: 46206 | D49: Cheque payment to Atlas Freight - CHQ-005319 | E49: CHQ-005319 | F49: -2327.04 | G49: MATCHED | H49: M00660
A50: L00046 | B50: 47 | C50: 46206 | D50: Receipt from Everest Textiles - INV-9204 | E50: INV-9204 | F50: 41743.69 | G50: MATCHED-REVIEW | H50: M01075 | I50: EX0070
A51: L00047 | B51: 48 | C51: 46207 | D51: Receipt from Kingsley Chemicals - INV-1047 | E51: INV-1047 | F51: 52971.86 | G51: MATCHED | H51: M00661
A52: L00048 | B52: 49 | C52: 46207 | D52: Receipt from Everest Textiles - INV-1053 | E52: INV-1053 | F52: 35711.75 | G52: MATCHED | H52: M00020
A53: L00049 | B53: 50 | C53: 46207 | D53: Receipt from Bluefin Logistics - INV-1338 | E53: INV-1338 | F53: 67468.06 | G53: MATCHED | H53: M00021
A54: L00050 | B54: 51 | C54: 46207 | D54: Receipt from Bluefin Logistics - INV-1350 | E54: INV-1350 | F54: 29463.69 | G54: MATCHED | H54: M00354
A55: L00051 | B55: 52 | C55: 46207 | D55: Receipt from Falcon Auto Parts - INV-1426 | E55: INV-1426 | F55: 61523.6 | G55: MATCHED | H55: M00022
A56: L00052 | B56: 53 | C56: 46207 | D56: Receipt from Acme Traders - INV-1517 | E56: INV-1517 | F56: 25701.64 | G56: MATCHED | H56: M00355
A57: L00053 | B57: 54 | C57: 46207 | D57: Receipt from Falcon Auto Parts - INV-1546 | E57: INV-1546 | F57: 26042.14 | G57: MATCHED | H57: M00023
A58: L00054 | B58: 55 | C58: 46207 | D58: Cheque payment to Kestrel Office Supplies - CHQ-005281 | E58: CHQ-005281 | F58: -19941.63 | G58: MATCHED | H58: M00964
A59: L00055 | B59: 56 | C59: 46207 | D59: Cheque payment to Summit Security - CHQ-005305 | E59: CHQ-005305 | F59: -5849.78 | G59: MATCHED | H59: M00878
A60: L00056 | B60: 57 | C60: 46207 | D60: Lumen Power Utility - bill | F60: -3537.85 | G60: MATCHED | H60: M01058
A61: L00057 | B61: 58 | C61: 46208 | D61: Receipt from Kingsley Chemicals - INV-1275 | E61: INV-1275 | F61: 80508.62 | G61: MATCHED | H61: M00356
A62: L00058 | B62: 59 | C62: 46208 | D62: Receipt from Lakeview Hotels - INV-1336 | E62: INV-1336 | F62: 18782.24 | G62: MATCHED | H62: M00024
A63: L00059 | B63: 60 | C63: 46208 | D63: Receipt from Greenleaf Agro - INV-1343 | E63: INV-1343 | F63: 21690.76 | G63: MATCHED | H63: M00025
A64: L00060 | B64: 61 | C64: 46208 | D64: Receipt from Everest Textiles - INV-1377 | E64: INV-1377 | F64: 38727.39 | G64: MATCHED | H64: M00026
A65: L00061 | B65: 62 | C65: 46208 | D65: Receipt from Lakeview Hotels - INV-1444 | E65: INV-1444 | F65: 19679.43 | G65: MATCHED | H65: M00357
A66: L00062 | B66: 63 | C66: 46208 | D66: Receipt from Indus Packaging - INV-1489 | E66: INV-1489 | F66: 4892.45 | G66: MATCHED | H66: M00027
A67: L00063 | B67: 64 | C67: 46208 | D67: Receipt from Acme Traders - INV-1493 | E67: INV-1493 | F67: 26367.59 | G67: MATCHED | H67: M00358
A68: L00064 | B68: 65 | C68: 46208 | D68: Receipt from Everest Textiles - INV-1509 | E68: INV-1509 | F68: 86957.99 | G68: MATCHED | H68: M00028
A69: L00065 | B69: 66 | C69: 46208 | D69: Receipt from Crestview Retail - INV-1567 | E69: INV-1567 | F69: 77182.34 | G69: MATCHED | H69: M00662
A70: L00066 | B70: 67 | C70: 46208 | D70: Cheque payment to Yonder Travel - CHQ-005038 | E70: CHQ-005038 | F70: -16889.14 | G70: MATCHED | H70: M00663
A71: L00067 | B71: 68 | C71: 46208 | D71: Cheque payment to Orchid Catering - CHQ-005164 | E71: CHQ-005164 | F71: -22663.12 | G71: MATCHED | H71: M00879
A72: L00068 | B72: 69 | C72: 46208 | D72: Cheque payment to Yonder Travel - CHQ-005228 | E72: CHQ-005228 | F72: -48127.03 | G72: MATCHED | H72: M00029
... A75: L00071 | B75: 72 | C75: 46208 | D75: Cheque payment to Birch Packaging - CHQ-005450 | E75: CHQ-005450 | F75: -49491.51 | G75: MATCHED | H75: M00664
...

Sheet Audit_Trail
A1: Audit Trail - provenance of this reconciliation
A2: Input hashes, parameters and rule counts. The hash of this workbook is recorded in the hash-chained audit_log.jsonl written beside it.
A4: Run
A5: run_id | B5: 0ED694B59281
A6: started_at | B6: 2026-10-13 08:09:18
A7: user | B7: root
A8: host | B8: vm
A9: tool_version | B9: 1.0.0
A10: python | B10: 3.12.3
A11: pandas | B11: 3.0.2
A13: Input files
A14: Source | B14: File | C14: Bytes | D14: SHA-256 | E14: Rows read | F14: Rows loaded | G14: Rows rejected
A15: BANK | B15: demo_bank_statement.csv | C15: 77531 | D15: 05d286d8974e076fd8dcdfefb4e14f58b34509e605bcbc7c99ed51350b76b097 | E15: 1130 | F15: 1130 | G15: 0
A16: LEDGER | B16: demo_ledger.csv | C16: 83575 | D16: d8954f33a675a8cfed3e8098126c85190572d7a6eba37064cfba91ff6eb1123f | E16: 1136 | F16: 1136 | G16: 0
A18: Matching parameters
A19: date_tolerance_days | B19: 3
A20: ref_date_window_days | B20: 15
A21: amount_tolerance | B21: 0
A22: desc_match_threshold | B22: 0.7
A23: mismatch_desc_threshold | B23: 0.75
A24: mismatch_max_pct | B24: 0.25
A25: rounding_threshold | B25: 1
A26: split_max_items | B26: 3
A27: split_date_window_days | B27: 5
A28: split_candidate_cap | B28: 25
A29: duplicate_window_days | B29: 1
A30: outstanding_days | B30: 5
... A32: medium_materiality | B32: 1000
A33: dayfirst | B33: =FALSE() -> FALSE
A34: bank_sign | B34: 1
A35: ledger_sign | B35: 1
A37: Rule execution log (in order)
A38: R1 Reference + Amount | B38: 1050
A39: R2 Amount + Date + Description | B39: 18
A40: R3 Reference match, amount differs | B40: 23
A41: R4 Amount + Date only | B41: 5
A42: R5 Split / batch (1:N) | B42: 6
A43: R6 Fuzzy description, amount differs | B43: 0
A45: Data-quality log: rows rejected on load (never silently dropped)
A46: Rejected rows | B46: None
